Hangman bot started
'757127742'
Traceback (most recent call last):
  File "/home/ubuntu/miniforge3/lib/python3.10/site-packages/pyrogram/dispatcher.py", line 240, in handler_worker
    await handler.callback(self.client, *args)
  File "/home/ubuntu/HangMan/game.py", line 638, in difficulty_callback
    user_name = player_stats[user_id]["name"]
KeyError: '757127742'
'757127742'
Traceback (most recent call last):
  File "/home/ubuntu/miniforge3/lib/python3.10/site-packages/pyrogram/dispatcher.py", line 240, in handler_worker
    await handler.callback(self.client, *args)
  File "/home/ubuntu/HangMan/game.py", line 638, in difficulty_callback
    user_name = player_stats[user_id]["name"]
KeyError: '757127742'
'757127742'
Traceback (most recent call last):
  File "/home/ubuntu/miniforge3/lib/python3.10/site-packages/pyrogram/dispatcher.py", line 240, in handler_worker
    await handler.callback(self.client, *args)
  File "/home/ubuntu/HangMan/game.py", line 638, in difficulty_callback
    user_name = player_stats[user_id]["name"]
KeyError: '757127742'
'757127742'
Traceback (most recent call last):
  File "/home/ubuntu/miniforge3/lib/python3.10/site-packages/pyrogram/dispatcher.py", line 240, in handler_worker
    await handler.callback(self.client, *args)
  File "/home/ubuntu/HangMan/game.py", line 638, in difficulty_callback
    user_name = player_stats[user_id]["name"]
KeyError: '757127742'
'757127742'
Traceback (most recent call last):
  File "/home/ubuntu/miniforge3/lib/python3.10/site-packages/pyrogram/dispatcher.py", line 240, in handler_worker
    await handler.callback(self.client, *args)
  File "/home/ubuntu/HangMan/game.py", line 638, in difficulty_callback
    user_name = player_stats[user_id]["name"]
KeyError: '757127742'
[hangman_bot] Waiting for 3 seconds before continuing (required by "messages.EditMessage")
'1606377072'
Traceback (most recent call last):
  File "/home/ubuntu/miniforge3/lib/python3.10/site-packages/pyrogram/dispatcher.py", line 240, in handler_worker
    await handler.callback(self.client, *args)
  File "/home/ubuntu/HangMan/game.py", line 638, in difficulty_callback
    user_name = player_stats[user_id]["name"]
KeyError: '1606377072'
'1606377072'
Traceback (most recent call last):
  File "/home/ubuntu/miniforge3/lib/python3.10/site-packages/pyrogram/dispatcher.py", line 240, in handler_worker
    await handler.callback(self.client, *args)
  File "/home/ubuntu/HangMan/game.py", line 638, in difficulty_callback
    user_name = player_stats[user_id]["name"]
KeyError: '1606377072'
'1606377072'
Traceback (most recent call last):
  File "/home/ubuntu/miniforge3/lib/python3.10/site-packages/pyrogram/dispatcher.py", line 240, in handler_worker
    await handler.callback(self.client, *args)
  File "/home/ubuntu/HangMan/game.py", line 638, in difficulty_callback
    user_name = player_stats[user_id]["name"]
KeyError: '1606377072'
'1606377072'
Traceback (most recent call last):
  File "/home/ubuntu/miniforge3/lib/python3.10/site-packages/pyrogram/dispatcher.py", line 240, in handler_worker
    await handler.callback(self.client, *args)
  File "/home/ubuntu/HangMan/game.py", line 638, in difficulty_callback
    user_name = player_stats[user_id]["name"]
KeyError: '1606377072'
'1606377072'
Traceback (most recent call last):
  File "/home/ubuntu/miniforge3/lib/python3.10/site-packages/pyrogram/dispatcher.py", line 240, in handler_worker
    await handler.callback(self.client, *args)
  File "/home/ubuntu/HangMan/game.py", line 638, in difficulty_callback
    user_name = player_stats[user_id]["name"]
KeyError: '1606377072'
'1606377072'
Traceback (most recent call last):
  File "/home/ubuntu/miniforge3/lib/python3.10/site-packages/pyrogram/dispatcher.py", line 240, in handler_worker
    await handler.callback(self.client, *args)
  File "/home/ubuntu/HangMan/game.py", line 638, in difficulty_callback
    user_name = player_stats[user_id]["name"]
KeyError: '1606377072'
'1606377072'
Traceback (most recent call last):
  File "/home/ubuntu/miniforge3/lib/python3.10/site-packages/pyrogram/dispatcher.py", line 240, in handler_worker
    await handler.callback(self.client, *args)
  File "/home/ubuntu/HangMan/game.py", line 638, in difficulty_callback
    user_name = player_stats[user_id]["name"]
KeyError: '1606377072'
'1606377072'
Traceback (most recent call last):
  File "/home/ubuntu/miniforge3/lib/python3.10/site-packages/pyrogram/dispatcher.py", line 240, in handler_worker
    await handler.callback(self.client, *args)
  File "/home/ubuntu/HangMan/game.py", line 638, in difficulty_callback
    user_name = player_stats[user_id]["name"]
KeyError: '1606377072'
'1606377072'
Traceback (most recent call last):
  File "/home/ubuntu/miniforge3/lib/python3.10/site-packages/pyrogram/dispatcher.py", line 240, in handler_worker
    await handler.callback(self.client, *args)
  File "/home/ubuntu/HangMan/game.py", line 638, in difficulty_callback
    user_name = player_stats[user_id]["name"]
KeyError: '1606377072'
'1606377072'
Traceback (most recent call last):
  File "/home/ubuntu/miniforge3/lib/python3.10/site-packages/pyrogram/dispatcher.py", line 240, in handler_worker
    await handler.callback(self.client, *args)
  File "/home/ubuntu/HangMan/game.py", line 638, in difficulty_callback
    user_name = player_stats[user_id]["name"]
KeyError: '1606377072'
'1606377072'
Traceback (most recent call last):
  File "/home/ubuntu/miniforge3/lib/python3.10/site-packages/pyrogram/dispatcher.py", line 240, in handler_worker
    await handler.callback(self.client, *args)
  File "/home/ubuntu/HangMan/game.py", line 638, in difficulty_callback
    user_name = player_stats[user_id]["name"]
KeyError: '1606377072'
'1606377072'
Traceback (most recent call last):
  File "/home/ubuntu/miniforge3/lib/python3.10/site-packages/pyrogram/dispatcher.py", line 240, in handler_worker
    await handler.callback(self.client, *args)
  File "/home/ubuntu/HangMan/game.py", line 638, in difficulty_callback
    user_name = player_stats[user_id]["name"]
KeyError: '1606377072'
'1606377072'
Traceback (most recent call last):
  File "/home/ubuntu/miniforge3/lib/python3.10/site-packages/pyrogram/dispatcher.py", line 240, in handler_worker
    await handler.callback(self.client, *args)
  File "/home/ubuntu/HangMan/game.py", line 638, in difficulty_callback
    user_name = player_stats[user_id]["name"]
KeyError: '1606377072'
'1606377072'
Traceback (most recent call last):
  File "/home/ubuntu/miniforge3/lib/python3.10/site-packages/pyrogram/dispatcher.py", line 240, in handler_worker
    await handler.callback(self.client, *args)
  File "/home/ubuntu/HangMan/game.py", line 638, in difficulty_callback
    user_name = player_stats[user_id]["name"]
KeyError: '1606377072'
'1606377072'
Traceback (most recent call last):
  File "/home/ubuntu/miniforge3/lib/python3.10/site-packages/pyrogram/dispatcher.py", line 240, in handler_worker
    await handler.callback(self.client, *args)
  File "/home/ubuntu/HangMan/game.py", line 638, in difficulty_callback
    user_name = player_stats[user_id]["name"]
KeyError: '1606377072'
'1606377072'
Traceback (most recent call last):
  File "/home/ubuntu/miniforge3/lib/python3.10/site-packages/pyrogram/dispatcher.py", line 240, in handler_worker
    await handler.callback(self.client, *args)
  File "/home/ubuntu/HangMan/game.py", line 638, in difficulty_callback
    user_name = player_stats[user_id]["name"]
KeyError: '1606377072'
'1606377072'
Traceback (most recent call last):
  File "/home/ubuntu/miniforge3/lib/python3.10/site-packages/pyrogram/dispatcher.py", line 240, in handler_worker
    await handler.callback(self.client, *args)
  File "/home/ubuntu/HangMan/game.py", line 638, in difficulty_callback
    user_name = player_stats[user_id]["name"]
KeyError: '1606377072'
'1606377072'
Traceback (most recent call last):
  File "/home/ubuntu/miniforge3/lib/python3.10/site-packages/pyrogram/dispatcher.py", line 240, in handler_worker
    await handler.callback(self.client, *args)
  File "/home/ubuntu/HangMan/game.py", line 638, in difficulty_callback
    user_name = player_stats[user_id]["name"]
KeyError: '1606377072'
'1606377072'
Traceback (most recent call last):
  File "/home/ubuntu/miniforge3/lib/python3.10/site-packages/pyrogram/dispatcher.py", line 240, in handler_worker
    await handler.callback(self.client, *args)
  File "/home/ubuntu/HangMan/game.py", line 638, in difficulty_callback
    user_name = player_stats[user_id]["name"]
KeyError: '1606377072'
'1606377072'
Traceback (most recent call last):
  File "/home/ubuntu/miniforge3/lib/python3.10/site-packages/pyrogram/dispatcher.py", line 240, in handler_worker
    await handler.callback(self.client, *args)
  File "/home/ubuntu/HangMan/game.py", line 638, in difficulty_callback
    user_name = player_stats[user_id]["name"]
KeyError: '1606377072'
'1606377072'
Traceback (most recent call last):
  File "/home/ubuntu/miniforge3/lib/python3.10/site-packages/pyrogram/dispatcher.py", line 240, in handler_worker
    await handler.callback(self.client, *args)
  File "/home/ubuntu/HangMan/game.py", line 638, in difficulty_callback
    user_name = player_stats[user_id]["name"]
KeyError: '1606377072'
'1606377072'
Traceback (most recent call last):
  File "/home/ubuntu/miniforge3/lib/python3.10/site-packages/pyrogram/dispatcher.py", line 240, in handler_worker
    await handler.callback(self.client, *args)
  File "/home/ubuntu/HangMan/game.py", line 638, in difficulty_callback
    user_name = player_stats[user_id]["name"]
KeyError: '1606377072'
'1606377072'
Traceback (most recent call last):
  File "/home/ubuntu/miniforge3/lib/python3.10/site-packages/pyrogram/dispatcher.py", line 240, in handler_worker
    await handler.callback(self.client, *args)
  File "/home/ubuntu/HangMan/game.py", line 638, in difficulty_callback
    user_name = player_stats[user_id]["name"]
KeyError: '1606377072'
'1606377072'
Traceback (most recent call last):
  File "/home/ubuntu/miniforge3/lib/python3.10/site-packages/pyrogram/dispatcher.py", line 240, in handler_worker
    await handler.callback(self.client, *args)
  File "/home/ubuntu/HangMan/game.py", line 638, in difficulty_callback
    user_name = player_stats[user_id]["name"]
KeyError: '1606377072'
'1606377072'
Traceback (most recent call last):
  File "/home/ubuntu/miniforge3/lib/python3.10/site-packages/pyrogram/dispatcher.py", line 240, in handler_worker
    await handler.callback(self.client, *args)
  File "/home/ubuntu/HangMan/game.py", line 638, in difficulty_callback
    user_name = player_stats[user_id]["name"]
KeyError: '1606377072'
'1606377072'
Traceback (most recent call last):
  File "/home/ubuntu/miniforge3/lib/python3.10/site-packages/pyrogram/dispatcher.py", line 240, in handler_worker
    await handler.callback(self.client, *args)
  File "/home/ubuntu/HangMan/game.py", line 638, in difficulty_callback
    user_name = player_stats[user_id]["name"]
KeyError: '1606377072'
'1606377072'
Traceback (most recent call last):
  File "/home/ubuntu/miniforge3/lib/python3.10/site-packages/pyrogram/dispatcher.py", line 240, in handler_worker
    await handler.callback(self.client, *args)
  File "/home/ubuntu/HangMan/game.py", line 638, in difficulty_callback
    user_name = player_stats[user_id]["name"]
KeyError: '1606377072'
'1606377072'
Traceback (most recent call last):
  File "/home/ubuntu/miniforge3/lib/python3.10/site-packages/pyrogram/dispatcher.py", line 240, in handler_worker
    await handler.callback(self.client, *args)
  File "/home/ubuntu/HangMan/game.py", line 638, in difficulty_callback
    user_name = player_stats[user_id]["name"]
KeyError: '1606377072'
'1606377072'
Traceback (most recent call last):
  File "/home/ubuntu/miniforge3/lib/python3.10/site-packages/pyrogram/dispatcher.py", line 240, in handler_worker
    await handler.callback(self.client, *args)
  File "/home/ubuntu/HangMan/game.py", line 638, in difficulty_callback
    user_name = player_stats[user_id]["name"]
KeyError: '1606377072'
'1606377072'
Traceback (most recent call last):
  File "/home/ubuntu/miniforge3/lib/python3.10/site-packages/pyrogram/dispatcher.py", line 240, in handler_worker
    await handler.callback(self.client, *args)
  File "/home/ubuntu/HangMan/game.py", line 638, in difficulty_callback
    user_name = player_stats[user_id]["name"]
KeyError: '1606377072'
'1606377072'
Traceback (most recent call last):
  File "/home/ubuntu/miniforge3/lib/python3.10/site-packages/pyrogram/dispatcher.py", line 240, in handler_worker
    await handler.callback(self.client, *args)
  File "/home/ubuntu/HangMan/game.py", line 638, in difficulty_callback
    user_name = player_stats[user_id]["name"]
KeyError: '1606377072'
'1606377072'
Traceback (most recent call last):
  File "/home/ubuntu/miniforge3/lib/python3.10/site-packages/pyrogram/dispatcher.py", line 240, in handler_worker
    await handler.callback(self.client, *args)
  File "/home/ubuntu/HangMan/game.py", line 638, in difficulty_callback
    user_name = player_stats[user_id]["name"]
KeyError: '1606377072'
'1606377072'
Traceback (most recent call last):
  File "/home/ubuntu/miniforge3/lib/python3.10/site-packages/pyrogram/dispatcher.py", line 240, in handler_worker
    await handler.callback(self.client, *args)
  File "/home/ubuntu/HangMan/game.py", line 638, in difficulty_callback
    user_name = player_stats[user_id]["name"]
KeyError: '1606377072'
'1606377072'
Traceback (most recent call last):
  File "/home/ubuntu/miniforge3/lib/python3.10/site-packages/pyrogram/dispatcher.py", line 240, in handler_worker
    await handler.callback(self.client, *args)
  File "/home/ubuntu/HangMan/game.py", line 638, in difficulty_callback
    user_name = player_stats[user_id]["name"]
KeyError: '1606377072'
'1606377072'
Traceback (most recent call last):
  File "/home/ubuntu/miniforge3/lib/python3.10/site-packages/pyrogram/dispatcher.py", line 240, in handler_worker
    await handler.callback(self.client, *args)
  File "/home/ubuntu/HangMan/game.py", line 638, in difficulty_callback
    user_name = player_stats[user_id]["name"]
KeyError: '1606377072'
'1606377072'
Traceback (most recent call last):
  File "/home/ubuntu/miniforge3/lib/python3.10/site-packages/pyrogram/dispatcher.py", line 240, in handler_worker
    await handler.callback(self.client, *args)
  File "/home/ubuntu/HangMan/game.py", line 638, in difficulty_callback
    user_name = player_stats[user_id]["name"]
KeyError: '1606377072'
'1606377072'
Traceback (most recent call last):
  File "/home/ubuntu/miniforge3/lib/python3.10/site-packages/pyrogram/dispatcher.py", line 240, in handler_worker
    await handler.callback(self.client, *args)
  File "/home/ubuntu/HangMan/game.py", line 638, in difficulty_callback
    user_name = player_stats[user_id]["name"]
KeyError: '1606377072'
'1606377072'
Traceback (most recent call last):
  File "/home/ubuntu/miniforge3/lib/python3.10/site-packages/pyrogram/dispatcher.py", line 240, in handler_worker
    await handler.callback(self.client, *args)
  File "/home/ubuntu/HangMan/game.py", line 638, in difficulty_callback
    user_name = player_stats[user_id]["name"]
KeyError: '1606377072'
'1606377072'
Traceback (most recent call last):
  File "/home/ubuntu/miniforge3/lib/python3.10/site-packages/pyrogram/dispatcher.py", line 240, in handler_worker
    await handler.callback(self.client, *args)
  File "/home/ubuntu/HangMan/game.py", line 638, in difficulty_callback
    user_name = player_stats[user_id]["name"]
KeyError: '1606377072'
'1606377072'
Traceback (most recent call last):
  File "/home/ubuntu/miniforge3/lib/python3.10/site-packages/pyrogram/dispatcher.py", line 240, in handler_worker
    await handler.callback(self.client, *args)
  File "/home/ubuntu/HangMan/game.py", line 638, in difficulty_callback
    user_name = player_stats[user_id]["name"]
KeyError: '1606377072'
'1606377072'
Traceback (most recent call last):
  File "/home/ubuntu/miniforge3/lib/python3.10/site-packages/pyrogram/dispatcher.py", line 240, in handler_worker
    await handler.callback(self.client, *args)
  File "/home/ubuntu/HangMan/game.py", line 638, in difficulty_callback
    user_name = player_stats[user_id]["name"]
KeyError: '1606377072'
'1606377072'
Traceback (most recent call last):
  File "/home/ubuntu/miniforge3/lib/python3.10/site-packages/pyrogram/dispatcher.py", line 240, in handler_worker
    await handler.callback(self.client, *args)
  File "/home/ubuntu/HangMan/game.py", line 638, in difficulty_callback
    user_name = player_stats[user_id]["name"]
KeyError: '1606377072'
'1606377072'
Traceback (most recent call last):
  File "/home/ubuntu/miniforge3/lib/python3.10/site-packages/pyrogram/dispatcher.py", line 240, in handler_worker
    await handler.callback(self.client, *args)
  File "/home/ubuntu/HangMan/game.py", line 638, in difficulty_callback
    user_name = player_stats[user_id]["name"]
KeyError: '1606377072'
'1606377072'
Traceback (most recent call last):
  File "/home/ubuntu/miniforge3/lib/python3.10/site-packages/pyrogram/dispatcher.py", line 240, in handler_worker
    await handler.callback(self.client, *args)
  File "/home/ubuntu/HangMan/game.py", line 638, in difficulty_callback
    user_name = player_stats[user_id]["name"]
KeyError: '1606377072'
'1606377072'
Traceback (most recent call last):
  File "/home/ubuntu/miniforge3/lib/python3.10/site-packages/pyrogram/dispatcher.py", line 240, in handler_worker
    await handler.callback(self.client, *args)
  File "/home/ubuntu/HangMan/game.py", line 638, in difficulty_callback
    user_name = player_stats[user_id]["name"]
KeyError: '1606377072'
'1606377072'
Traceback (most recent call last):
  File "/home/ubuntu/miniforge3/lib/python3.10/site-packages/pyrogram/dispatcher.py", line 240, in handler_worker
    await handler.callback(self.client, *args)
  File "/home/ubuntu/HangMan/game.py", line 638, in difficulty_callback
    user_name = player_stats[user_id]["name"]
KeyError: '1606377072'
'1606377072'
Traceback (most recent call last):
  File "/home/ubuntu/miniforge3/lib/python3.10/site-packages/pyrogram/dispatcher.py", line 240, in handler_worker
    await handler.callback(self.client, *args)
  File "/home/ubuntu/HangMan/game.py", line 638, in difficulty_callback
    user_name = player_stats[user_id]["name"]
KeyError: '1606377072'
'1606377072'
Traceback (most recent call last):
  File "/home/ubuntu/miniforge3/lib/python3.10/site-packages/pyrogram/dispatcher.py", line 240, in handler_worker
    await handler.callback(self.client, *args)
  File "/home/ubuntu/HangMan/game.py", line 638, in difficulty_callback
    user_name = player_stats[user_id]["name"]
KeyError: '1606377072'
'1606377072'
Traceback (most recent call last):
  File "/home/ubuntu/miniforge3/lib/python3.10/site-packages/pyrogram/dispatcher.py", line 240, in handler_worker
    await handler.callback(self.client, *args)
  File "/home/ubuntu/HangMan/game.py", line 638, in difficulty_callback
    user_name = player_stats[user_id]["name"]
KeyError: '1606377072'
'1606377072'
Traceback (most recent call last):
  File "/home/ubuntu/miniforge3/lib/python3.10/site-packages/pyrogram/dispatcher.py", line 240, in handler_worker
    await handler.callback(self.client, *args)
  File "/home/ubuntu/HangMan/game.py", line 638, in difficulty_callback
    user_name = player_stats[user_id]["name"]
KeyError: '1606377072'
'1606377072'
Traceback (most recent call last):
  File "/home/ubuntu/miniforge3/lib/python3.10/site-packages/pyrogram/dispatcher.py", line 240, in handler_worker
    await handler.callback(self.client, *args)
  File "/home/ubuntu/HangMan/game.py", line 638, in difficulty_callback
    user_name = player_stats[user_id]["name"]
KeyError: '1606377072'
'1606377072'
Traceback (most recent call last):
  File "/home/ubuntu/miniforge3/lib/python3.10/site-packages/pyrogram/dispatcher.py", line 240, in handler_worker
    await handler.callback(self.client, *args)
  File "/home/ubuntu/HangMan/game.py", line 638, in difficulty_callback
    user_name = player_stats[user_id]["name"]
KeyError: '1606377072'
'1606377072'
Traceback (most recent call last):
  File "/home/ubuntu/miniforge3/lib/python3.10/site-packages/pyrogram/dispatcher.py", line 240, in handler_worker
    await handler.callback(self.client, *args)
  File "/home/ubuntu/HangMan/game.py", line 638, in difficulty_callback
    user_name = player_stats[user_id]["name"]
KeyError: '1606377072'
'1606377072'
Traceback (most recent call last):
  File "/home/ubuntu/miniforge3/lib/python3.10/site-packages/pyrogram/dispatcher.py", line 240, in handler_worker
    await handler.callback(self.client, *args)
  File "/home/ubuntu/HangMan/game.py", line 638, in difficulty_callback
    user_name = player_stats[user_id]["name"]
KeyError: '1606377072'
'1606377072'
Traceback (most recent call last):
  File "/home/ubuntu/miniforge3/lib/python3.10/site-packages/pyrogram/dispatcher.py", line 240, in handler_worker
    await handler.callback(self.client, *args)
  File "/home/ubuntu/HangMan/game.py", line 638, in difficulty_callback
    user_name = player_stats[user_id]["name"]
KeyError: '1606377072'
'1606377072'
Traceback (most recent call last):
  File "/home/ubuntu/miniforge3/lib/python3.10/site-packages/pyrogram/dispatcher.py", line 240, in handler_worker
    await handler.callback(self.client, *args)
  File "/home/ubuntu/HangMan/game.py", line 638, in difficulty_callback
    user_name = player_stats[user_id]["name"]
KeyError: '1606377072'
'1606377072'
Traceback (most recent call last):
  File "/home/ubuntu/miniforge3/lib/python3.10/site-packages/pyrogram/dispatcher.py", line 240, in handler_worker
    await handler.callback(self.client, *args)
  File "/home/ubuntu/HangMan/game.py", line 638, in difficulty_callback
    user_name = player_stats[user_id]["name"]
KeyError: '1606377072'
'1606377072'
Traceback (most recent call last):
  File "/home/ubuntu/miniforge3/lib/python3.10/site-packages/pyrogram/dispatcher.py", line 240, in handler_worker
    await handler.callback(self.client, *args)
  File "/home/ubuntu/HangMan/game.py", line 638, in difficulty_callback
    user_name = player_stats[user_id]["name"]
KeyError: '1606377072'
'1606377072'
Traceback (most recent call last):
  File "/home/ubuntu/miniforge3/lib/python3.10/site-packages/pyrogram/dispatcher.py", line 240, in handler_worker
    await handler.callback(self.client, *args)
  File "/home/ubuntu/HangMan/game.py", line 638, in difficulty_callback
    user_name = player_stats[user_id]["name"]
KeyError: '1606377072'
'1606377072'
Traceback (most recent call last):
  File "/home/ubuntu/miniforge3/lib/python3.10/site-packages/pyrogram/dispatcher.py", line 240, in handler_worker
    await handler.callback(self.client, *args)
  File "/home/ubuntu/HangMan/game.py", line 638, in difficulty_callback
    user_name = player_stats[user_id]["name"]
KeyError: '1606377072'
'1606377072'
Traceback (most recent call last):
  File "/home/ubuntu/miniforge3/lib/python3.10/site-packages/pyrogram/dispatcher.py", line 240, in handler_worker
    await handler.callback(self.client, *args)
  File "/home/ubuntu/HangMan/game.py", line 638, in difficulty_callback
    user_name = player_stats[user_id]["name"]
KeyError: '1606377072'
'1606377072'
Traceback (most recent call last):
  File "/home/ubuntu/miniforge3/lib/python3.10/site-packages/pyrogram/dispatcher.py", line 240, in handler_worker
    await handler.callback(self.client, *args)
  File "/home/ubuntu/HangMan/game.py", line 638, in difficulty_callback
    user_name = player_stats[user_id]["name"]
KeyError: '1606377072'
'1606377072'
Traceback (most recent call last):
  File "/home/ubuntu/miniforge3/lib/python3.10/site-packages/pyrogram/dispatcher.py", line 240, in handler_worker
    await handler.callback(self.client, *args)
  File "/home/ubuntu/HangMan/game.py", line 638, in difficulty_callback
    user_name = player_stats[user_id]["name"]
KeyError: '1606377072'
'1606377072'
Traceback (most recent call last):
  File "/home/ubuntu/miniforge3/lib/python3.10/site-packages/pyrogram/dispatcher.py", line 240, in handler_worker
    await handler.callback(self.client, *args)
  File "/home/ubuntu/HangMan/game.py", line 638, in difficulty_callback
    user_name = player_stats[user_id]["name"]
KeyError: '1606377072'
'1606377072'
Traceback (most recent call last):
  File "/home/ubuntu/miniforge3/lib/python3.10/site-packages/pyrogram/dispatcher.py", line 240, in handler_worker
    await handler.callback(self.client, *args)
  File "/home/ubuntu/HangMan/game.py", line 638, in difficulty_callback
    user_name = player_stats[user_id]["name"]
KeyError: '1606377072'
'1606377072'
Traceback (most recent call last):
  File "/home/ubuntu/miniforge3/lib/python3.10/site-packages/pyrogram/dispatcher.py", line 240, in handler_worker
    await handler.callback(self.client, *args)
  File "/home/ubuntu/HangMan/game.py", line 638, in difficulty_callback
    user_name = player_stats[user_id]["name"]
KeyError: '1606377072'
'1606377072'
Traceback (most recent call last):
  File "/home/ubuntu/miniforge3/lib/python3.10/site-packages/pyrogram/dispatcher.py", line 240, in handler_worker
    await handler.callback(self.client, *args)
  File "/home/ubuntu/HangMan/game.py", line 638, in difficulty_callback
    user_name = player_stats[user_id]["name"]
KeyError: '1606377072'
'1606377072'
Traceback (most recent call last):
  File "/home/ubuntu/miniforge3/lib/python3.10/site-packages/pyrogram/dispatcher.py", line 240, in handler_worker
    await handler.callback(self.client, *args)
  File "/home/ubuntu/HangMan/game.py", line 638, in difficulty_callback
    user_name = player_stats[user_id]["name"]
KeyError: '1606377072'
'1606377072'
Traceback (most recent call last):
  File "/home/ubuntu/miniforge3/lib/python3.10/site-packages/pyrogram/dispatcher.py", line 240, in handler_worker
    await handler.callback(self.client, *args)
  File "/home/ubuntu/HangMan/game.py", line 638, in difficulty_callback
    user_name = player_stats[user_id]["name"]
KeyError: '1606377072'
'1606377072'
Traceback (most recent call last):
  File "/home/ubuntu/miniforge3/lib/python3.10/site-packages/pyrogram/dispatcher.py", line 240, in handler_worker
    await handler.callback(self.client, *args)
  File "/home/ubuntu/HangMan/game.py", line 638, in difficulty_callback
    user_name = player_stats[user_id]["name"]
KeyError: '1606377072'
'6715831051'
Traceback (most recent call last):
  File "/home/ubuntu/miniforge3/lib/python3.10/site-packages/pyrogram/dispatcher.py", line 240, in handler_worker
    await handler.callback(self.client, *args)
  File "/home/ubuntu/HangMan/game.py", line 638, in difficulty_callback
    user_name = player_stats[user_id]["name"]
KeyError: '6715831051'
'6715831051'
Traceback (most recent call last):
  File "/home/ubuntu/miniforge3/lib/python3.10/site-packages/pyrogram/dispatcher.py", line 240, in handler_worker
    await handler.callback(self.client, *args)
  File "/home/ubuntu/HangMan/game.py", line 638, in difficulty_callback
    user_name = player_stats[user_id]["name"]
KeyError: '6715831051'
'6715831051'
Traceback (most recent call last):
  File "/home/ubuntu/miniforge3/lib/python3.10/site-packages/pyrogram/dispatcher.py", line 240, in handler_worker
    await handler.callback(self.client, *args)
  File "/home/ubuntu/HangMan/game.py", line 638, in difficulty_callback
    user_name = player_stats[user_id]["name"]
KeyError: '6715831051'
'1606377072'
Traceback (most recent call last):
  File "/home/ubuntu/miniforge3/lib/python3.10/site-packages/pyrogram/dispatcher.py", line 240, in handler_worker
    await handler.callback(self.client, *args)
  File "/home/ubuntu/HangMan/game.py", line 638, in difficulty_callback
    user_name = player_stats[user_id]["name"]
KeyError: '1606377072'
'6715831051'
Traceback (most recent call last):
  File "/home/ubuntu/miniforge3/lib/python3.10/site-packages/pyrogram/dispatcher.py", line 240, in handler_worker
    await handler.callback(self.client, *args)
  File "/home/ubuntu/HangMan/game.py", line 638, in difficulty_callback
    user_name = player_stats[user_id]["name"]
KeyError: '6715831051'
'6715831051'
Traceback (most recent call last):
  File "/home/ubuntu/miniforge3/lib/python3.10/site-packages/pyrogram/dispatcher.py", line 240, in handler_worker
    await handler.callback(self.client, *args)
  File "/home/ubuntu/HangMan/game.py", line 638, in difficulty_callback
    user_name = player_stats[user_id]["name"]
KeyError: '6715831051'
'1606377072'
Traceback (most recent call last):
  File "/home/ubuntu/miniforge3/lib/python3.10/site-packages/pyrogram/dispatcher.py", line 240, in handler_worker
    await handler.callback(self.client, *args)
  File "/home/ubuntu/HangMan/game.py", line 638, in difficulty_callback
    user_name = player_stats[user_id]["name"]
KeyError: '1606377072'
'1606377072'
Traceback (most recent call last):
  File "/home/ubuntu/miniforge3/lib/python3.10/site-packages/pyrogram/dispatcher.py", line 240, in handler_worker
    await handler.callback(self.client, *args)
  File "/home/ubuntu/HangMan/game.py", line 638, in difficulty_callback
    user_name = player_stats[user_id]["name"]
KeyError: '1606377072'
'1606377072'
Traceback (most recent call last):
  File "/home/ubuntu/miniforge3/lib/python3.10/site-packages/pyrogram/dispatcher.py", line 240, in handler_worker
    await handler.callback(self.client, *args)
  File "/home/ubuntu/HangMan/game.py", line 638, in difficulty_callback
    user_name = player_stats[user_id]["name"]
KeyError: '1606377072'
'1606377072'
Traceback (most recent call last):
  File "/home/ubuntu/miniforge3/lib/python3.10/site-packages/pyrogram/dispatcher.py", line 240, in handler_worker
    await handler.callback(self.client, *args)
  File "/home/ubuntu/HangMan/game.py", line 638, in difficulty_callback
    user_name = player_stats[user_id]["name"]
KeyError: '1606377072'
'1606377072'
Traceback (most recent call last):
  File "/home/ubuntu/miniforge3/lib/python3.10/site-packages/pyrogram/dispatcher.py", line 240, in handler_worker
    await handler.callback(self.client, *args)
  File "/home/ubuntu/HangMan/game.py", line 638, in difficulty_callback
    user_name = player_stats[user_id]["name"]
KeyError: '1606377072'
'1606377072'
Traceback (most recent call last):
  File "/home/ubuntu/miniforge3/lib/python3.10/site-packages/pyrogram/dispatcher.py", line 240, in handler_worker
    await handler.callback(self.client, *args)
  File "/home/ubuntu/HangMan/game.py", line 638, in difficulty_callback
    user_name = player_stats[user_id]["name"]
KeyError: '1606377072'
'1606377072'
Traceback (most recent call last):
  File "/home/ubuntu/miniforge3/lib/python3.10/site-packages/pyrogram/dispatcher.py", line 240, in handler_worker
    await handler.callback(self.client, *args)
  File "/home/ubuntu/HangMan/game.py", line 638, in difficulty_callback
    user_name = player_stats[user_id]["name"]
KeyError: '1606377072'
'1606377072'
Traceback (most recent call last):
  File "/home/ubuntu/miniforge3/lib/python3.10/site-packages/pyrogram/dispatcher.py", line 240, in handler_worker
    await handler.callback(self.client, *args)
  File "/home/ubuntu/HangMan/game.py", line 638, in difficulty_callback
    user_name = player_stats[user_id]["name"]
KeyError: '1606377072'
'1606377072'
Traceback (most recent call last):
  File "/home/ubuntu/miniforge3/lib/python3.10/site-packages/pyrogram/dispatcher.py", line 240, in handler_worker
    await handler.callback(self.client, *args)
  File "/home/ubuntu/HangMan/game.py", line 638, in difficulty_callback
    user_name = player_stats[user_id]["name"]
KeyError: '1606377072'
'1606377072'
Traceback (most recent call last):
  File "/home/ubuntu/miniforge3/lib/python3.10/site-packages/pyrogram/dispatcher.py", line 240, in handler_worker
    await handler.callback(self.client, *args)
  File "/home/ubuntu/HangMan/game.py", line 638, in difficulty_callback
    user_name = player_stats[user_id]["name"]
KeyError: '1606377072'
'1606377072'
Traceback (most recent call last):
  File "/home/ubuntu/miniforge3/lib/python3.10/site-packages/pyrogram/dispatcher.py", line 240, in handler_worker
    await handler.callback(self.client, *args)
  File "/home/ubuntu/HangMan/game.py", line 638, in difficulty_callback
    user_name = player_stats[user_id]["name"]
KeyError: '1606377072'
'1606377072'
Traceback (most recent call last):
  File "/home/ubuntu/miniforge3/lib/python3.10/site-packages/pyrogram/dispatcher.py", line 240, in handler_worker
    await handler.callback(self.client, *args)
  File "/home/ubuntu/HangMan/game.py", line 638, in difficulty_callback
    user_name = player_stats[user_id]["name"]
KeyError: '1606377072'
'1606377072'
Traceback (most recent call last):
  File "/home/ubuntu/miniforge3/lib/python3.10/site-packages/pyrogram/dispatcher.py", line 240, in handler_worker
    await handler.callback(self.client, *args)
  File "/home/ubuntu/HangMan/game.py", line 638, in difficulty_callback
    user_name = player_stats[user_id]["name"]
KeyError: '1606377072'
'1606377072'
Traceback (most recent call last):
  File "/home/ubuntu/miniforge3/lib/python3.10/site-packages/pyrogram/dispatcher.py", line 240, in handler_worker
    await handler.callback(self.client, *args)
  File "/home/ubuntu/HangMan/game.py", line 638, in difficulty_callback
    user_name = player_stats[user_id]["name"]
KeyError: '1606377072'
'1606377072'
Traceback (most recent call last):
  File "/home/ubuntu/miniforge3/lib/python3.10/site-packages/pyrogram/dispatcher.py", line 240, in handler_worker
    await handler.callback(self.client, *args)
  File "/home/ubuntu/HangMan/game.py", line 638, in difficulty_callback
    user_name = player_stats[user_id]["name"]
KeyError: '1606377072'
'1606377072'
Traceback (most recent call last):
  File "/home/ubuntu/miniforge3/lib/python3.10/site-packages/pyrogram/dispatcher.py", line 240, in handler_worker
    await handler.callback(self.client, *args)
  File "/home/ubuntu/HangMan/game.py", line 638, in difficulty_callback
    user_name = player_stats[user_id]["name"]
KeyError: '1606377072'
'1606377072'
Traceback (most recent call last):
  File "/home/ubuntu/miniforge3/lib/python3.10/site-packages/pyrogram/dispatcher.py", line 240, in handler_worker
    await handler.callback(self.client, *args)
  File "/home/ubuntu/HangMan/game.py", line 638, in difficulty_callback
    user_name = player_stats[user_id]["name"]
KeyError: '1606377072'
'1606377072'
Traceback (most recent call last):
  File "/home/ubuntu/miniforge3/lib/python3.10/site-packages/pyrogram/dispatcher.py", line 240, in handler_worker
    await handler.callback(self.client, *args)
  File "/home/ubuntu/HangMan/game.py", line 638, in difficulty_callback
    user_name = player_stats[user_id]["name"]
KeyError: '1606377072'
'1606377072'
Traceback (most recent call last):
  File "/home/ubuntu/miniforge3/lib/python3.10/site-packages/pyrogram/dispatcher.py", line 240, in handler_worker
    await handler.callback(self.client, *args)
  File "/home/ubuntu/HangMan/game.py", line 638, in difficulty_callback
    user_name = player_stats[user_id]["name"]
KeyError: '1606377072'
'1606377072'
Traceback (most recent call last):
  File "/home/ubuntu/miniforge3/lib/python3.10/site-packages/pyrogram/dispatcher.py", line 240, in handler_worker
    await handler.callback(self.client, *args)
  File "/home/ubuntu/HangMan/game.py", line 638, in difficulty_callback
    user_name = player_stats[user_id]["name"]
KeyError: '1606377072'
'1606377072'
Traceback (most recent call last):
  File "/home/ubuntu/miniforge3/lib/python3.10/site-packages/pyrogram/dispatcher.py", line 240, in handler_worker
    await handler.callback(self.client, *args)
  File "/home/ubuntu/HangMan/game.py", line 638, in difficulty_callback
    user_name = player_stats[user_id]["name"]
KeyError: '1606377072'
'1606377072'
Traceback (most recent call last):
  File "/home/ubuntu/miniforge3/lib/python3.10/site-packages/pyrogram/dispatcher.py", line 240, in handler_worker
    await handler.callback(self.client, *args)
  File "/home/ubuntu/HangMan/game.py", line 638, in difficulty_callback
    user_name = player_stats[user_id]["name"]
KeyError: '1606377072'
'1606377072'
Traceback (most recent call last):
  File "/home/ubuntu/miniforge3/lib/python3.10/site-packages/pyrogram/dispatcher.py", line 240, in handler_worker
    await handler.callback(self.client, *args)
  File "/home/ubuntu/HangMan/game.py", line 638, in difficulty_callback
    user_name = player_stats[user_id]["name"]
KeyError: '1606377072'
'1606377072'
Traceback (most recent call last):
  File "/home/ubuntu/miniforge3/lib/python3.10/site-packages/pyrogram/dispatcher.py", line 240, in handler_worker
    await handler.callback(self.client, *args)
  File "/home/ubuntu/HangMan/game.py", line 638, in difficulty_callback
    user_name = player_stats[user_id]["name"]
KeyError: '1606377072'
'1606377072'
Traceback (most recent call last):
  File "/home/ubuntu/miniforge3/lib/python3.10/site-packages/pyrogram/dispatcher.py", line 240, in handler_worker
    await handler.callback(self.client, *args)
  File "/home/ubuntu/HangMan/game.py", line 638, in difficulty_callback
    user_name = player_stats[user_id]["name"]
KeyError: '1606377072'
'1606377072'
Traceback (most recent call last):
  File "/home/ubuntu/miniforge3/lib/python3.10/site-packages/pyrogram/dispatcher.py", line 240, in handler_worker
    await handler.callback(self.client, *args)
  File "/home/ubuntu/HangMan/game.py", line 638, in difficulty_callback
    user_name = player_stats[user_id]["name"]
KeyError: '1606377072'
'1606377072'
Traceback (most recent call last):
  File "/home/ubuntu/miniforge3/lib/python3.10/site-packages/pyrogram/dispatcher.py", line 240, in handler_worker
    await handler.callback(self.client, *args)
  File "/home/ubuntu/HangMan/game.py", line 638, in difficulty_callback
    user_name = player_stats[user_id]["name"]
KeyError: '1606377072'
'1606377072'
Traceback (most recent call last):
  File "/home/ubuntu/miniforge3/lib/python3.10/site-packages/pyrogram/dispatcher.py", line 240, in handler_worker
    await handler.callback(self.client, *args)
  File "/home/ubuntu/HangMan/game.py", line 638, in difficulty_callback
    user_name = player_stats[user_id]["name"]
KeyError: '1606377072'
'1606377072'
Traceback (most recent call last):
  File "/home/ubuntu/miniforge3/lib/python3.10/site-packages/pyrogram/dispatcher.py", line 240, in handler_worker
    await handler.callback(self.client, *args)
  File "/home/ubuntu/HangMan/game.py", line 638, in difficulty_callback
    user_name = player_stats[user_id]["name"]
KeyError: '1606377072'
'1606377072'
Traceback (most recent call last):
  File "/home/ubuntu/miniforge3/lib/python3.10/site-packages/pyrogram/dispatcher.py", line 240, in handler_worker
    await handler.callback(self.client, *args)
  File "/home/ubuntu/HangMan/game.py", line 638, in difficulty_callback
    user_name = player_stats[user_id]["name"]
KeyError: '1606377072'
'1606377072'
Traceback (most recent call last):
  File "/home/ubuntu/miniforge3/lib/python3.10/site-packages/pyrogram/dispatcher.py", line 240, in handler_worker
    await handler.callback(self.client, *args)
  File "/home/ubuntu/HangMan/game.py", line 638, in difficulty_callback
    user_name = player_stats[user_id]["name"]
KeyError: '1606377072'
'1606377072'
Traceback (most recent call last):
  File "/home/ubuntu/miniforge3/lib/python3.10/site-packages/pyrogram/dispatcher.py", line 240, in handler_worker
    await handler.callback(self.client, *args)
  File "/home/ubuntu/HangMan/game.py", line 638, in difficulty_callback
    user_name = player_stats[user_id]["name"]
KeyError: '1606377072'
'1606377072'
Traceback (most recent call last):
  File "/home/ubuntu/miniforge3/lib/python3.10/site-packages/pyrogram/dispatcher.py", line 240, in handler_worker
    await handler.callback(self.client, *args)
  File "/home/ubuntu/HangMan/game.py", line 638, in difficulty_callback
    user_name = player_stats[user_id]["name"]
KeyError: '1606377072'
'1606377072'
Traceback (most recent call last):
  File "/home/ubuntu/miniforge3/lib/python3.10/site-packages/pyrogram/dispatcher.py", line 240, in handler_worker
    await handler.callback(self.client, *args)
  File "/home/ubuntu/HangMan/game.py", line 638, in difficulty_callback
    user_name = player_stats[user_id]["name"]
KeyError: '1606377072'
'1606377072'
Traceback (most recent call last):
  File "/home/ubuntu/miniforge3/lib/python3.10/site-packages/pyrogram/dispatcher.py", line 240, in handler_worker
    await handler.callback(self.client, *args)
  File "/home/ubuntu/HangMan/game.py", line 638, in difficulty_callback
    user_name = player_stats[user_id]["name"]
KeyError: '1606377072'
'1606377072'
Traceback (most recent call last):
  File "/home/ubuntu/miniforge3/lib/python3.10/site-packages/pyrogram/dispatcher.py", line 240, in handler_worker
    await handler.callback(self.client, *args)
  File "/home/ubuntu/HangMan/game.py", line 638, in difficulty_callback
    user_name = player_stats[user_id]["name"]
KeyError: '1606377072'
'1606377072'
Traceback (most recent call last):
  File "/home/ubuntu/miniforge3/lib/python3.10/site-packages/pyrogram/dispatcher.py", line 240, in handler_worker
    await handler.callback(self.client, *args)
  File "/home/ubuntu/HangMan/game.py", line 638, in difficulty_callback
    user_name = player_stats[user_id]["name"]
KeyError: '1606377072'
'1606377072'
Traceback (most recent call last):
  File "/home/ubuntu/miniforge3/lib/python3.10/site-packages/pyrogram/dispatcher.py", line 240, in handler_worker
    await handler.callback(self.client, *args)
  File "/home/ubuntu/HangMan/game.py", line 638, in difficulty_callback
    user_name = player_stats[user_id]["name"]
KeyError: '1606377072'
'1606377072'
Traceback (most recent call last):
  File "/home/ubuntu/miniforge3/lib/python3.10/site-packages/pyrogram/dispatcher.py", line 240, in handler_worker
    await handler.callback(self.client, *args)
  File "/home/ubuntu/HangMan/game.py", line 638, in difficulty_callback
    user_name = player_stats[user_id]["name"]
KeyError: '1606377072'
'1606377072'
Traceback (most recent call last):
  File "/home/ubuntu/miniforge3/lib/python3.10/site-packages/pyrogram/dispatcher.py", line 240, in handler_worker
    await handler.callback(self.client, *args)
  File "/home/ubuntu/HangMan/game.py", line 638, in difficulty_callback
    user_name = player_stats[user_id]["name"]
KeyError: '1606377072'
'1606377072'
Traceback (most recent call last):
  File "/home/ubuntu/miniforge3/lib/python3.10/site-packages/pyrogram/dispatcher.py", line 240, in handler_worker
    await handler.callback(self.client, *args)
  File "/home/ubuntu/HangMan/game.py", line 638, in difficulty_callback
    user_name = player_stats[user_id]["name"]
KeyError: '1606377072'
'1606377072'
Traceback (most recent call last):
  File "/home/ubuntu/miniforge3/lib/python3.10/site-packages/pyrogram/dispatcher.py", line 240, in handler_worker
    await handler.callback(self.client, *args)
  File "/home/ubuntu/HangMan/game.py", line 638, in difficulty_callback
    user_name = player_stats[user_id]["name"]
KeyError: '1606377072'
Hangman bot started
